Workbook

Sheet Kapak
B2: İmga.AI — Kullanıcı Kabul Testi (UAT)
B3: Web Paneli · app.imga.ai · İş kullanıcısı gözüyle uçtan uca kabul testi
B5: Ürün | C5: İmga.AI — Türkçe müşteri yorumu analiz platformu
B6: Kapsam | C6: Web paneli (login, panel, analitik, ticket, veri yükleme, aksiyon, ayarlar, admin, roller, çaprazlar)
B7: Ortam | C7: Staging: https://staging.imga.ai (tercih) · Prod smoke: https://app.imga.ai
B8: Sürüm / Tarih | C8: v1.0 · __ / __ / 2026
B9: Toplam senaryo | C9: 153 senaryo / 10 modül
B10: Hazırlayan | C10: Ürün ekibi
B12: Nasıl kullanılır
B13: 1) 'Roller & Ortam' sayfasını oku; test hesaplarını ve ortamı hazırla.
B14: 2) Sorumlu olduğun modül sayfasını aç. Her satır bir test senaryosudur.
B15: 3) 'Ön Koşul'u sağla → 'Test Adımları'nı sırayla uygula → 'Beklenen Sonuç' ile karşılaştır.
B16: 4) 'Gerçekleşen Sonuç'u yaz; 'Durum'u seç (Geçti/Kaldı/Bloke/Uygulanamaz); 'Test Eden' + 'Tarih' doldur.
B17: 5) 'Kaldı' ise 'Hata Kaydı' sayfasına detayı gir (ekran görüntüsüyle). 'Özet' sayfası otomatik güncellenir.
B19: Durum değerleri
B20: Geçti | C20: Beklenen sonuç birebir gerçekleşti.
B21: Kaldı | C21: Beklenenden sapma / hata var → Hata Kaydı'na gir.
B22: Bloke | C22: Bir ön koşul/başka hata yüzünden test edilemedi.
B23: Uygulanamaz | C23: Bu ortam/rol için geçerli değil.
B25: Öncelik / Şiddet
B26: Kritik | C26: Temel akış çalışmıyor / veri kaybı / yetki ihlali. Yayın engelleyici.
B27: Yüksek | C27: Önemli özellik bozuk, geçici çözüm olabilir.
B28: Orta | C28: İkincil özellik yanlış; akış devam ediyor.
B29: Düşük | C29: Görsel / metin / yazım; işlevi etkilemiyor.

Sheet Özet
B2: UAT İlerleme Özeti
B4: Modül | C4: Toplam | D4: Geçti | E4: Kaldı | F4: Bloke | G4: Uygulanamaz | H4: Kalan | I4: Başarı %
B5: 01 · Kimlik Doğrulama | C5: =COUNTA('01 · Kimlik Doğrulama'!A3:A17) | D5: =COUNTIF('01 · Kimlik Doğrulama'!H3:H17,"Geçti") | E5: =COUNTIF('01 · Kimlik Doğrulama'!H3:H17,"Kaldı") | F5: =COUNTIF('01 · Kimlik Doğrulama'!H3:H17,"Bloke") | G5: =COUNTIF('01 · Kimlik Doğrulama'!H3:H17,"Uygulanamaz") | H5: =C5-D5-E5-F5-G5 | I5: =IF((D5+E5)=0,"—",D5/(D5+E5))
B6: 02 · Panel & Yönetici Özeti | C6: =COUNTA('02 · Panel & Yönetici Özeti'!A3:A20) | D6: =COUNTIF('02 · Panel & Yönetici Özeti'!H3:H20,"Geçti") | E6: =COUNTIF('02 · Panel & Yönetici Özeti'!H3:H20,"Kaldı") | F6: =COUNTIF('02 · Panel & Yönetici Özeti'!H3:H20,"Bloke") | G6: =COUNTIF('02 · Panel & Yönetici Özeti'!H3:H20,"Uygulanamaz") | H6: =C6-D6-E6-F6-G6 | I6: =IF((D6+E6)=0,"—",D6/(D6+E6))
B7: 03 · Analitik | C7: =COUNTA('03 · Analitik'!A3:A17) | D7: =COUNTIF('03 · Analitik'!H3:H17,"Geçti") | E7: =COUNTIF('03 · Analitik'!H3:H17,"Kaldı") | F7: =COUNTIF('03 · Analitik'!H3:H17,"Bloke") | G7: =COUNTIF('03 · Analitik'!H3:H17,"Uygulanamaz") | H7: =C7-D7-E7-F7-G7 | I7: =IF((D7+E7)=0,"—",D7/(D7+E7))
B8: 04 · Ticket Operasyonu | C8: =COUNTA('04 · Ticket Operasyonu'!A3:A27) | D8: =COUNTIF('04 · Ticket Operasyonu'!H3:H27,"Geçti") | E8: =COUNTIF('04 · Ticket Operasyonu'!H3:H27,"Kaldı") | F8: =COUNTIF('04 · Ticket Operasyonu'!H3:H27,"Bloke") | G8: =COUNTIF('04 · Ticket Operasyonu'!H3:H27,"Uygulanamaz") | H8: =C8-D8-E8-F8-G8 | I8: =IF((D8+E8)=0,"—",D8/(D8+E8))
B9: 05 · Veri Yükleme | C9: =COUNTA('05 · Veri Yükleme'!A3:A26) | D9: =COUNTIF('05 · Veri Yükleme'!H3:H26,"Geçti") | E9: =COUNTIF('05 · Veri Yükleme'!H3:H26,"Kaldı") | F9: =COUNTIF('05 · Veri Yükleme'!H3:H26,"Bloke") | G9: =COUNTIF('05 · Veri Yükleme'!H3:H26,"Uygulanamaz") | H9: =C9-D9-E9-F9-G9 | I9: =IF((D9+E9)=0,"—",D9/(D9+E9))
B10: 06 · Aksiyon & Uyarılar | C10: =COUNTA('06 · Aksiyon & Uyarılar'!A3:A13) | D10: =COUNTIF('06 · Aksiyon & Uyarılar'!H3:H13,"Geçti") | E10: =COUNTIF('06 · Aksiyon & Uyarılar'!H3:H13,"Kaldı") | F10: =COUNTIF('06 · Aksiyon & Uyarılar'!H3:H13,"Bloke") | G10: =COUNTIF('06 · Aksiyon & Uyarılar'!H3:H13,"Uygulanamaz") | H10: =C10-D10-E10-F10-G10 | I10: =IF((D10+E10)=0,"—",D10/(D10+E10))
B11: 07 · Ayarlar | C11: =COUNTA('07 · Ayarlar'!A3:A18) | D11: =COUNTIF('07 · Ayarlar'!H3:H18,"Geçti") | E11: =COUNTIF('07 · Ayarlar'!H3:H18,"Kaldı") | F11: =COUNTIF('07 · Ayarlar'!H3:H18,"Bloke") | G11: =COUNTIF('07 · Ayarlar'!H3:H18,"Uygulanamaz") | H11: =C11-D11-E11-F11-G11 | I11: =IF((D11+E11)=0,"—",D11/(D11+E11))
B12: 08 · Yönetim - Admin | C12: =COUNTA('08 · Yönetim - Admin'!A3:A14) | D12: =COUNTIF('08 · Yönetim - Admin'!H3:H14,"Geçti") | E12: =COUNTIF('08 · Yönetim - Admin'!H3:H14,"Kaldı") | F12: =COUNTIF('08 · Yönetim - Admin'!H3:H14,"Bloke") | G12: =COUNTIF('08 · Yönetim - Admin'!H3:H14,"Uygulanamaz") | H12: =C12-D12-E12-F12-G12 | I12: =IF((D12+E12)=0,"—",D12/(D12+E12))
B13: 09 · Roller & Yetkiler (RBAC) | C13: =COUNTA('09 · Roller & Yetkiler (RBAC)'!A3:A8) | D13: =COUNTIF('09 · Roller & Yetkiler (RBAC)'!H3:H8,"Geçti") | E13: =COUNTIF('09 · Roller & Yetkiler (RBAC)'!H3:H8,"Kaldı") | F13: =COUNTIF('09 · Roller & Yetkiler (RBAC)'!H3:H8,"Bloke") | G13: =COUNTIF('09 · Roller & Yetkiler (RBAC)'!H3:H8,"Uygulanamaz") | H13: =C13-D13-E13-F13-G13 | I13: =IF((D13+E13)=0,"—",D13/(D13+E13))
B14: 10 · Genel - Çapraz | C14: =COUNTA('10 · Genel - Çapraz'!A3:A13) | D14: =COUNTIF('10 · Genel - Çapraz'!H3:H13,"Geçti") | E14: =COUNTIF('10 · Genel - Çapraz'!H3:H13,"Kaldı") | F14: =COUNTIF('10 · Genel - Çapraz'!H3:H13,"Bloke") | G14: =COUNTIF('10 · Genel - Çapraz'!H3:H13,"Uygulanamaz") | H14: =C14-D14-E14-F14-G14 | I14: =IF((D14+E14)=0,"—",D14/(D14+E14))
B15: TOPLAM | C15: =SUM(C5:C14) | D15: =SUM(D5:D14) | E15: =SUM(E5:E14) | F15: =SUM(F5:F14) | G15: =SUM(G5:G14) | H15: =SUM(H5:H14) | I15: =IF((D15+E15)=0,"—",D15/(D15+E15))
B17: Genel durum dağılımı
B18: Geçti | C18: =D15
B19: Kaldı | C19: =E15
B20: Bloke | C20: =F15
B21: Kalan | C21: =H15

Sheet Roller & Ortam
B2: Roller, Test Hesapları ve Ortam
B4: Roller (4 yetki seviyesi)
B5: Rol | C5: UI'da | D5: Ne yapabilir | E5: Tipik kişi
B6: Süper-yönetici | C6: (tüm kurumlar üstü) | D6: Tüm kurumları yönetir; kurum açar/siler; sistem denetim sayfaları. | E6: İmga.AI ekibi
B7: Yönetici | C7: tenant_admin | D7: Kurumda tam yetki: ayarlar, davet, her ticket, raporlar. | E7: Müşteri firma ürün lideri
B8: Analist | C8: analyst | D8: Ticket'ta çalışır (üstlen, çöz, yorum, müşteri yanıtı). Ayar değiştiremez. | E8: Müşteri hizmetleri ekibi
B9: İzleyici | C9: viewer | D9: Yalnız okur + iç not. Durum değiştiremez, müşteriye yazamaz. | E9: Üst yönetim / paydaş
B11: Test hesapları (doldur)
B12: Kurum / Rol | C12: E-posta | D12: Şifre | E12: Not
B13: Süper-yönetici · —
B14: Kurum A · Yönetici
B15: Kurum A · Analist
B16: Kurum A · İzleyici
B17: Kurum B · Yönetici
B18: Çok-kurumlu kullanıcı · A: Analist / B: İzleyici | E18: tenant-switch testleri için
B20: Ortam ve tarayıcı
B21: Konu | C21: Değer
B22: Staging (UAT) | C22: https://staging.imga.ai — tüm UAT burada koşulur
B23: Production (smoke) | C23: https://app.imga.ai — yalnız yayın sonrası duman testi
B24: Tarayıcı | C24: Chrome (güncel) birincil; mümkünse Edge + Safari
B25: Temiz oturum | C25: Yeni hesap/davet testinde gizli (incognito) pencere; Ctrl+F5 hard refresh

Sheet 01 · Kimlik Doğrulama
A1: İmga UAT — 01 · Kimlik Doğrulama (15 senaryo)
A2: Test ID | B2: Kategori | C2: Senaryo | D2: Ön Koşul | E2: Test Adımları | F2: Beklenen Sonuç | G2: Gerçekleşen Sonuç | H2: Durum | I2: Öncelik | J2: Test Eden | K2: Tarih | L2: Not / Hata No
A3: UAT-AUTH-01 | B3: A. Giriş (/login) | C3: Başarılı giriş | D3: Herhangi bir geçerli hesap. | E3: 1. https://staging.imga.ai/login aç. 2. E-posta ve şifreni gir. 3. "Giriş yap" butonuna bas. | F3: • Sayfa başlığı "imga.ai", alt başlık "Hesabınıza giriş yapın". • Buton basılınca "Giriş yapılıyor..." gösteriliyor. • Başarılı giriş → / (Panel) açılıyor. | I3: Yüksek
A4: UAT-AUTH-02 | B4: A. Giriş (/login) | C4: Yanlış şifre | D4: Geçerli e-posta, yanlış şifre. | E4: 1. E-postanı doğru, şifreni yanlış gir → "Giriş yap". | F4: • Hata bildirimi: başlık "Giriş başarısız", açıklama "E-posta veya şifre hatalı." • Sayfada kalınıyor, panele geçilmiyor. | I4: Yüksek
A5: UAT-AUTH-03 | B5: A. Giriş (/login) | C5: Olmayan hesap (bilgi sızdırmama) | D5: Kayıtlı olmayan bir e-posta. | E5: 1. Var olmayan bir e-posta + herhangi bir şifre → "Giriş yap". | F5: • Aynı genel hata mesajı ("E-posta veya şifre hatalı.") — hangi e-postaların kayıtlı olduğu sızdırılmıyor. | I5: Kritik
A6: UAT-AUTH-04 | B6: A. Giriş (/login) | C6: Oturum sona erince yönlendirme | D6: Giriş yapılmış oturum. | E6: 1. Uzun süre işlem yapmadan bekle (token süresi dolana dek) veya ürün ekibinden oturumu geçersiz kılmasını iste. 2. Bir sayfaya geçiş yapmayı dene. | F6: • Login'e yönlendiriliyor; üstte amber uyarı: "Oturumunuz sona erdi. Lütfen tekrar giriş yapın." • Tekrar giriş yapınca kaldığın yere/panele dönüyorsun. | I6: Yüksek
A7: UAT-AUTH-05 | B7: A. Giriş (/login) | C7: Giriş yapmadan korumalı sayfa | D7: Çıkış yapılmış / hiç giriş yapılmamış. | E7: 1. Doğrudan https://staging.imga.ai/tickets URL'sini aç. | F7: • Login'e yönlendiriliyor; giriş yapmadan korumalı içerik görünmüyor. | I7: Yüksek
A8: UAT-AUTH-06 | B8: B. Davet Kabul (/invite/{token}) | C8: Yeni kullanıcı daveti kabul | D8: Sistemde olmayan bir e-postaya gönderilmiş geçerli davet. | E8: 1. Davet linkini gizli (incognito) pencerede aç. 2. Önizleme bloğunu doğrula (kurum adı + rol rozeti + davet edilen e-posta + geçerlilik). 3. "Yeni hesap oluştur" formunu doldur: Tam adınız + Şifre (≥ 8 karakter) + Şifre tekrar. 4. "Daveti kabul et"'e bas. | F8: • Bildirim: "Hesap oluşturuldu" + "{kurum} ekibine hoş geldin." • Otomatik giriş yapılıp / paneline yönlendiriliyor. | I8: Yüksek
A9: UAT-AUTH-07 | B9: B. Davet Kabul (/invite/{token}) | C9: Şifre doğrulamaları (yeni kullanıcı) | D9: Geçerli yeni-kullanıcı daveti. | E9: 1. Şifre ile Şifre tekrar'ı farklı gir → kabul et. 2. Şifreyi 8 karakterden kısa gir → kabul et. | F9: • Farklı şifreler → "Şifreler eşleşmiyor." • Kısa şifre → "Şifre en az 8 karakter olmalı." | I9: Yüksek
A10: UAT-AUTH-08 | B10: B. Davet Kabul (/invite/{token}) | C10: Mevcut kullanıcı daveti kabul | D10: Sistemde kayıtlı bir e-postaya gönderilmiş davet. | E10: 1. Daveti aç → "Mevcut hesap ile katıl" formu görünür. 2. Açıklamayı oku: "Bu e-posta zaten kayıtlı. Şifrenle doğrulayıp kuruma ekleneceksin — yeni hesap açılmıyor." 3. O hesabın şifresini gir → "Hesabımla daveti kabul et". | F10: • Bildirim: "Davet kabul edildi" + "{kurum} artık kurum listende." • Panele yönlendiriliyor; yeni kurum, kurum listesine ekleniyor. | I10: Yüksek
A11: UAT-AUTH-09 | B11: B. Davet Kabul (/invite/{token}) | C11: Başka hesapla giriş yapmışken farklı davet | D11: A kullanıcısı olarak giriş yapılmış; davet B e-postasına gelmiş. | E11: 1. A olarak girişliyken B'ye gelen daveti aç. | F11: • Amber uyarı: "Şu an {A e-postası} hesabıyla giriş yapmışsın ama davet {B e-postası} içindi. Aşağıya o hesabın şifresini gir; oturum yeni hesaba geçecek." | I11: Yüksek
A12: UAT-AUTH-10 | B12: B. Davet Kabul (/invite/{token}) | C12: Geçersiz / süresi dolmuş davet | D12: Bozuk veya süresi geçmiş bir davet token'ı. | E12: 1. Geçersiz bir davet linkini aç (örn. token'ın sonunu boz). | F12: • Kırmızı kalkan ikonu + "Bu davet geçersiz veya süresi dolmuş." • "Lütfen kurum yöneticinizle iletişime geçip yeni bir davet isteyin." • "Giriş ekranına dön" butonu → /login. | I12: Yüksek
A13: UAT-AUTH-11 | B13: B. Davet Kabul (/invite/{token}) | C13: Yanlış şifre (mevcut kullanıcı daveti) | D13: Geçerli mevcut-kullanıcı daveti. | E13: 1. Mevcut hesap formunda yanlış şifre gir → kabul et. | F13: • Hata: "Şifre hatalı." (Davet başka e-posta içinse: "Bu davet farklı bir e-posta için.") | I13: Yüksek
A14: UAT-AUTH-12 | B14: C. Çok-Kurumlu Geçiş (Tenant Switcher) | C14: Kurumlar arası geçiş | D14: Çok-kurumlu kullanıcı (Kurum A + Kurum B üyesi). | E14: 1. Giriş yap. Sol menünün üstündeki kurum seçiciye tıkla. 2. Açılan listede aktif kurumda ✓ işareti, diğer kurumların rol etiketini doğrula. 3. Kurum B'yi seç. | F14: • Bildirim: "Kurum değiştirildi". • Sayfa Kurum B verisini gösteriyor; rolün B'deki rolüne göre değişiyor (örn. B'de izleyiciysen ayar sayfaları kısıtlı). • Tekrar seçiciden Kurum A'ya dönülebiliyor. | I14: Yüksek
... A17: UAT-AUTH-15 | B17: D. Çıkış | C17: Çıkış yapma | D17: Girişli kullanıcı. | E17: 1. Sol menünün altındaki kullanıcı menüsünü (avatar) aç. 2. Üstte ad + e-postanı doğrula. 3. "Çıkış yap"'a tıkla. | F17: • /login'e yönlendiriliyor. • Geri tuşuyla korumalı sayfaya dönülemiyor (tekrar login isteniyor). | I17: Yüksek

Sheet 02 · Panel & Yönetici Özeti
A1: İmga UAT — 02 · Panel & Yönetici Özeti (18 senaryo)
A2: Test ID | B2: Kategori | C2: Senaryo | D2: Ön Koşul | E2: Test Adımları | F2: Beklenen Sonuç | G2: Gerçekleşen Sonuç | H2: Durum | I2: Öncelik | J2: Test Eden | K2: Tarih | L2: Not / Hata No
A3: UAT-PNL-01 | B3: A. Panel / Dashboard (/) | C3: Panel açılışı (dolu veri) | D3: Herhangi bir rol · Kurum A'da analizli veri var. | E3: 1. Giriş yap (veya sol menü → Panel). | F3: • Üstte "Merhaba, {ad}" + aktif kurum adı + bugünün tarihi (Türkçe). • Memnuniyet kartı: "Genel müşteri memnuniyeti" etiketi, büyük yüzde (0'dan sayarak animasyonla artar), tek cümlelik durum (örn. "Müşterileriniz memnun."), altında "Toplam {n} yorumdan {x} tanesi olumlu, {y} tanesi olumsuz." • Renkli memnuniyet çubuğu (Olumlu/Nötr/Olumsuz segmentleri). | I3: Orta
A4: UAT-PNL-02 | B4: A. Panel / Dashboard (/) | C4: Boş kurumda "ilk dosya" çağrısı | D4: Herhangi bir rol · Kurum B (boş). | E4: 1. Kurum B'ye geç, Panel'i aç. | F4: • Boş durum: "Müşterilerinizin sesini dinlemeye başlayın" + açıklama + "İlk dosyanızı yükleyin" butonu (→ /analyze/upload). • Yapay/karmaşık görünmüyor; sade bir davet ekranı. | I4: Orta
A5: UAT-PNL-03 | B5: A. Panel / Dashboard (/) | C5: "Bu ayki önceliğiniz" | D5: Kurum A'da en az bir SWOT üretilmiş (öneri içeren). | E5: 1. Panel'de "Bu ayki önceliğiniz" kartını incele. | F5: • En öncelikli SWOT önerisinin başlığı + açıklaması görünüyor. • "Aksiyon planının tamamını gör" linki → /strategy. • (SWOT yoksa bu kart hiç görünmez — bu da doğru davranış.) | I5: Orta
A6: UAT-PNL-04 | B6: A. Panel / Dashboard (/) | C6: En çok şikayet edilen konular | D6: Kurum A · negatif yorumlar var. | E6: 1. "En çok şikayet edilen konular" kartına bak. 2. Bir konu satırına tıkla. | F6: • Her satırda: sıra no, kategori, "{n} olumsuz yorum · şikayetlerin %{x}'i", kırmızı oran çubuğu, örnek alıntı. • Satıra tıklayınca Analiz Arşivi o kategori + NEGATİF filtresiyle açılıyor. | I6: Orta
A7: UAT-PNL-05 | B7: A. Panel / Dashboard (/) | C7: Müşterinin Sesi | D7: Kurum A. | E7: 1. "Müşterinin Sesi" kartını incele. 2. Bir alıntı kartına tıkla. | F7: • Gerçek yorum alıntıları + duygu rozeti (Olumlu/Nötr/Olumsuz) + kategori + "X saat önce". • Tıklayınca Analiz Arşivi ilgili filtreyle açılıyor. | I7: Orta
A8: UAT-PNL-06 | B8: A. Panel / Dashboard (/) | C8: Hızlı yükleme (sürükle-bırak) | D8: Analist/Yönetici · temiz.xlsx. | E8: 1. Sağ raydaki "Hızlı yükleme" alanına temiz.xlsx'i sürükle-bırak. 2. İlerlemeyi izle. | F8: • "Dosya yükleniyor…" → ilerleme çubuğu → "Analiz tamamlandı" + "{x} yorum analiz edildi. Yukarıdaki rapor güncellendi." • "Sonuçları gör" butonu çalışıyor. • Standart dışı kolonlu dosyada hata mesajı çıkıp "gelişmiş yükleme" (/analyze/upload) öneriliyor. | I8: Orta
A9: UAT-PNL-07 | B9: A. Panel / Dashboard (/) | C9: Hızlı işlemler + yönetici özeti şeridi | D9: Kurum A. | E9: 1. Sağ raydaki "Hızlı işlemler" linklerini (Yönetici Özeti / SWOT-OKR / Ticket'lar / Rapor indir) tek tek dene. 2. Panelde "Yönetici Özeti" şeridini incele (varsa son brifing başlığı). | F9: • 4 hızlı link doğru sayfalara gidiyor. • Brifing varsa başlık + ilk içgörüler + "Özetin tamamını gör"; yoksa "Yönetici özetinizi oluşturun" çağrısı. | I9: Orta
A10: UAT-PNL-08 | B10: A. Panel / Dashboard (/) | C10: Sınıflandırma kalitesi çipi | D10: Kurum A · "belirsiz" oranı > %5 olan veri. | E10: 1. Panelde sınıflandırma kalitesi çipini bul (oran düşükse görünür). | F10: • Durum etiketi (İyi / İyileştirilebilir / Düşük) + açıklama; tıklayınca /insights?tab=category açılıyor. • Oran ≤ %5 ise çip hiç görünmez (doğru davranış). | I10: Orta
A11: UAT-EXB-01 | B11: B. Yönetici Özeti (/executive-briefing) | C11: Anahtar yokken uyarı | D11: Aktif Gemini anahtarı olmayan kurum. | E11: 1. Sol menü → Yönetici Özeti. | F11: • Amber uyarı: "Yönetici özeti oluşturmak için Gemini API anahtarı gerekli." • "Anahtar ekle" butonu → /settings/integrations. • "Yeni özet üret" butonu pasif. | I11: Orta
A12: UAT-EXB-02 | B12: B. Yönetici Özeti (/executive-briefing) | C12: Yeni özet üretme | D12: Aktif Gemini anahtarı olan, verili Kurum A. | E12: 1. Dönem'i seç (Haftalık / Aylık / Üç aylık). 2. "Yeni özet üret"'e bas, üretimi bekle. | F12: • Üretim sırasında buton spinner gösteriyor. • Bitince bildirim "Brifing hazır."; yeni brifing otomatik seçiliyor. • Detayda: başlık, KPI Değişimleri, Kritik İçgörüler, Öncelikli Aksiyonlar bölümleri. | I12: Orta
A13: UAT-EXB-03 | B13: B. Yönetici Özeti (/executive-briefing) | C13: Öncelikli aksiyonlara gitme | D13: Brifing üretilmiş (UAT-EXB-02). | E13: 1. Detayda Öncelikli Aksiyonlar altında bir aksiyon kartına tıkla. | F13: • İlgili aksiyon kalemine (/action-items/...) gidiliyor (bağlı aksiyon varsa). | I13: Orta
A14: UAT-EXB-04 | B14: B. Yönetici Özeti (/executive-briefing) | C14: Geçmiş özetler | D14: En az 2 brifing üretilmiş. | E14: 1. "Geçmiş Özetler" listesinden eski bir özette "Görüntüle"'ye bas. | F14: • Seçilen özet detayda açılıyor; URL güncelleniyor (paylaşılabilir). • Hiç yoksa: "Henüz brifing yok." | I14: Orta
... A20: UAT-STR-06 | B20: C. Strateji (/strategy) | C20: Geçmiş sekmesi ve filtre | D20: Birden çok rapor var. | E20: 1. "Geçmiş" sekmesine geç. 2. Tür filtresini SWOT / OKR / Tümü arasında değiştir. 3. Bir rapora "Görüntüle", sonra "PDF" dene; sayfalama varsa gez. | F20: • Liste türe göre filtreleniyor, "{n} kayıt" sayacı doğru. • Görüntüle ilgili sekmeyi açıyor; PDF iniyor. • Hiç yoksa: "Henüz rapor yok." | I20: Orta

Sheet 03 · Analitik
A1: İmga UAT — 03 · Analitik (15 senaryo)
A2: Test ID | B2: Kategori | C2: Senaryo | D2: Ön Koşul | E2: Test Adımları | F2: Beklenen Sonuç | G2: Gerçekleşen Sonuç | H2: Durum | I2: Öncelik | J2: Test Eden | K2: Tarih | L2: Not / Hata No
A3: UAT-INS-01 | B3: A. İçgörüler (/insights) | C3: Sayfa ve filtre çubuğu | D3: Herhangi bir rol · Kurum A. | E3: 1. Sol menü → Analitik → İçgörüler. 2. Başlangıç / Bitiş tarihleri ve Kaynak (Tümü / Sadece Manuel / Sadece Toplu) filtrelerini dene. | F3: • Başlık "İçgörüler", alt başlık "Duygu, kategori ve Ticket metriklerinin ayrıntılı görünümü." • Tarih boşken bilgi rozeti: "Tüm zamanlar" + "Filtre uygulanmadı — başlangıç ve bitiş seçerek daraltın." • Tarih/kaynak değişimi grafikleri güncelliyor ve URL'ye yansıyor. | I3: Orta
A4: UAT-INS-02 | B4: A. İçgörüler (/insights) | C4: Duygu sekmesi (3 grafik) | D4: Kurum A. | E4: 1. Duygu sekmesini aç. | F4: • "Duygu Dağılımı" (halka grafik), "Skor Histogramı" (çubuk), "Duygu Trendi (gün)" (çizgi) görünüyor. • Renk kodları tutarlı (negatif kırmızı, nötr gri, pozitif yeşil). | I4: Orta
A5: UAT-INS-03 | B5: A. İçgörüler (/insights) | C5: Kategori ve Çapraz (drill-down) | D5: Kurum A. | E5: 1. Kategori sekmesi → "Kategori Top 10" çubuk grafiğini gör. 2. Çapraz sekmesi → "Kategori × Duygu Matrisi"'nde bir hücreye tıkla. | F5: • Matris hücresine tıklayınca Analiz Arşivi ilgili kategori + duygu filtresiyle açılıyor. • "Belirsiz" kategori tablonun en altında. | I5: Orta
A6: UAT-INS-04 | B6: A. İçgörüler (/insights) | C6: NPS ve Ticket sekmeleri | D6: Kurum A · NPS verisi ve çözülmüş ticket'lar var. | E6: 1. NPS sekmesi → büyük skor + bucket dağılımı + aylık trendi gör. 2. Ticket sekmesi → çözüm süresi dağılımı + Ortalama/Ortanca/p95 kartları. | F6: • NPS skoru görünüyor (veri yoksa "—"); bucket pastası (Detractor/Passive/Promoter). • Çözüm süresi istatistikleri "saat" cinsinden. | I6: Orta
A7: UAT-INS-05 | B7: A. İçgörüler (/insights) | C7: Isı haritası (eksen seçimi + drill-down) | D7: Kurum A. | E7: 1. Isı haritası sekmesi → X/Y eksenlerini ve Metrik'i seç. 2. Aynı ekseni X ve Y'ye koymayı dene. 3. Dolu bir hücreye tıkla. | F7: • X=Y olursa: "X ve Y eksenleri farklı olmalı." uyarısı. • Hücreye tıklayınca Analiz Arşivi ilgili zaman filtresiyle açılıyor. | I7: Orta
A8: UAT-INS-06 | B8: A. İçgörüler (/insights) | C8: Kohort, Kelimeler, Perspektif, Kural Katmanları | D8: Kurum A. | E8: 1. Kohort: Dönem/Boyut/Top kohort kontrollerini değiştir. 2. Kelimeler: Duygu/Kategori/İkili kelimeler ile kelime bulutunu süz. 3. Perspektif: "Şirket Perspektifi Top 10"da bir bara tıkla. 4. Kural Katmanları: katman tetikleme grafiğini gör. | F8: • Her sekme veri gösteriyor veya "Bu filtrelerle veri bulunamadı." boş durumu veriyor; uygulama çökmüyor. • Perspektif barına tıklayınca Analiz Arşivi perspektif filtresiyle açılıyor. | I8: Orta
A9: UAT-INS-07 | B9: A. İçgörüler (/insights) | C9: Sekme/filtre URL kalıcılığı | D9: Kurum A. | E9: 1. Bir sekme + tarih filtresi seç. 2. Sayfayı yenile (F5); sonra tarayıcı geri/ileri tuşlarını dene. 3. URL'yi kopyalayıp yeni sekmede aç. | F9: • Yenileme ve geri/ileri seçimi koruyor; kopyalanan URL aynı görünümü açıyor. | I9: Orta
A10: UAT-REV-01 | B10: B. Analiz Arşivi (/reviews) | C10: Liste ve sayaç | D10: Kurum A. | E10: 1. Sol menü → Analitik → Analiz Arşivi. | F10: • Başlık "Analiz Arşivi", alt başlık "Tüm analizler — manuel ve toplu giriş bir arada. {n} kayıt". • Her satır: yorum metni (2 satır), duygu rozeti (Olumlu/Nötr/Olumsuz), kategori, tarih, kaynak; ticket varsa "Ticket var", düzeltme varsa "düzeltildi" rozeti. Sol kenar duygu rengiyle çizgili. | I10: Orta
A11: UAT-REV-02 | B11: B. Analiz Arşivi (/reviews) | C11: Perspektif ve yükleme filtreleri + pill'ler | D11: Kurum A · taksonomi + en az bir toplu yükleme var. | E11: 1. "Şirket perspektifi" açılırından bir-iki perspektif seç. 2. "Yükleme seç" açılırından bir yükleme seç. 3. Üstte beliren filtre pill'lerinden birine tıklayıp temizle. | F11: • Seçimler listeyi daraltıyor; aktif filtreler pill olarak görünüyor (örn. "Yükleme: ab12cd34…", "Duygu: Olumsuz"). • Pill'e tıklamak o filtreyi temizliyor. | I11: Orta
A12: UAT-REV-03 | B12: B. Analiz Arşivi (/reviews) | C12: Sonsuz kaydırma / "Daha fazla göster" | D12: Kurum A · 50'den fazla analiz. | E12: 1. Listenin altına in → "Daha fazla göster"'e bas. | F12: • Sonraki sayfa ekleniyor; tüm kayıtlar bitince buton kayboluyor. • Eşleşme yoksa: "Bu filtrelerle eşleşen analiz yok" + "Filtreleri temizleyin ya da yeni bir dosya yükleyin." | I12: Orta
A13: UAT-REV-04 | B13: B. Analiz Arşivi (/reviews) | C13: Analiz detayı | D13: Kurum A. | E13: 1. Bir analiz satırına tıkla → detay sayfası. | F13: • "← Analizler" geri linki. • Kartlar: tarih+metin; Duygu/Skor(final)/Skor(raw, BERT)/Güven; Şirket Perspektifi; Kural Katmanları; Karar (örn. "Ticket Açıldı" / "Atlandı (…)"). • Ticket'a bağlıysa "Ticket'a Git →" görünüyor. | I13: Orta
A14: UAT-REV-05 | B14: B. Analiz Arşivi (/reviews) | C14: "Kararı Düzelt" (model eğitimi) | D14: Analist/Yönetici · Bir analiz detayı. | E14: 1. "Kararı Düzelt" butonuna bas. 2. Duygu/Kategori'yi değiştir, opsiyonel gerekçe yaz → "Düzeltmeyi Kaydet". | F14: • Düzeltme anında yansıyor; analiz güncelleniyor. • (İzleyici ile bu buton/işlem kısıtlı olmalı — modül 09'da doğrulanır.) | I14: Orta
... A17: UAT-RPT-02 | B17: C. Raporlar (/reports) | C17: Rapor indirme ve silme | D17: En az bir tamamlanmış rapor. | E17: 1. Listede tamamlanmış raporda "İndir"'e bas. 2. Sonra çöp/sil ikonuyla raporu sil, onayla. | F17: • Dosya iniyor; tip ve formatla tutarlı. • Silme onayı "Raporu silmek istediğinizden emin misiniz?"; onayınca "Rapor silindi." • Liste boşsa: "Henüz rapor yok. Üstteki Yeni Rapor butonu ile…" | I17: Kritik

Sheet 04 · Ticket Operasyonu
A1: İmga UAT — 04 · Ticket Operasyonu (25 senaryo)
A2: Test ID | B2: Kategori | C2: Senaryo | D2: Ön Koşul | E2: Test Adımları | F2: Beklenen Sonuç | G2: Gerçekleşen Sonuç | H2: Durum | I2: Öncelik | J2: Test Eden | K2: Tarih | L2: Not / Hata No
A3: UAT-TKT-01 | B3: A. Ticket Listesi (/tickets) | C3: Listeyi açma ve sayaç | D3: Analist · Kurum A'da en az 5 ticket var. | E3: 1. Sol menüden Operasyon → Ticket'lar'a tıkla. 2. Sayfanın açılmasını bekle. | F3: • Sayfa başlığı "Ticket'lar". • Başlık altında sayaç: "{gösterilen} Ticket gösteriliyor / toplam {toplam}". • Ticket'lar satır satır listeleniyor; her satırda başlık, kategori, öncelik, durum ve atanan görünüyor. | I3: Yüksek
A4: UAT-TKT-02 | B4: A. Ticket Listesi (/tickets) | C4: Durum filtresi (çoklu seçim) | D4: Analist · Farklı durumlarda ticket'lar var. | E4: 1. Durum filtresine tıkla; açılan listede Açık ve İlerlemekte'yi seç. 2. Listenin güncellenmesini izle. 3. Tarayıcının adres çubuğundaki (URL) değişimi gözlemle. | F4: • Liste yalnız Açık + İlerlemekte ticket'ları gösteriyor. • Sayaç güncelleniyor. • URL filtreyi içeriyor (örn. ?state=open,in_progress benzeri) — bu URL başkasıyla paylaşılınca aynı filtreli görünüm açılmalı. | I4: Yüksek
A5: UAT-TKT-03 | B5: A. Ticket Listesi (/tickets) | C5: Öncelik, Kategori ve Atanan filtreleri | D5: Analist. | E5: 1. Öncelik filtresinden Acil + Yüksek seç. 2. Kategori filtresinden bir kategori seç. 3. Atanan filtresinden "Bana atananlar" seç. | F5: • Her filtre listeyi daraltıyor; sonuçlar seçili kriterlere uyuyor. • "Atanan: Bana atananlar" yalnız sana atanmış ticket'ları gösteriyor. | I5: Yüksek
A6: UAT-TKT-04 | B6: A. Ticket Listesi (/tickets) | C6: Filtreleri temizleme | D6: Analist · En az bir filtre aktif (önceki senaryodan). | E6: 1. "Filtreleri temizle" butonuna tıkla. | F6: • Tüm filtreler sıfırlanıyor, liste tüm ticket'ları gösteriyor. • URL'den filtre parametreleri kalkıyor. • "Filtreleri temizle" butonu (artık aktif filtre yok) gizleniyor. | I6: Yüksek
A7: UAT-TKT-05 | B7: A. Ticket Listesi (/tickets) | C7: "Daha fazla göster" (sayfalama) | D7: Analist · Kurum A'da 100'den fazla ticket olmalı (yoksa bu senaryoyu "uygulanamaz" işaretle). | E7: 1. Listenin en altına in. 2. "Daha fazla göster ({kalan} kaldı)" butonuna tıkla. | F7: • Sonraki ticket grubu listenin altına ekleniyor (mevcutlar kaybolmadan). • Tüm ticket'lar yüklendiğinde buton kayboluyor. | I7: Yüksek
A8: UAT-TKT-06 | B8: A. Ticket Listesi (/tickets) | C8: Filtreyle eşleşen yokken boş durum | D8: Analist. | E8: 1. Hiç ticket'ın olmayacağı bir filtre kombinasyonu seç (örn. Durum: İptal + Kategori: çok nadir bir kategori). | F8: • Liste boş; "Bu filtrelerle eşleşen ticket yok." benzeri mesaj görünüyor. • Uygulama çökmüyor, hata vermiyor. | I8: Yüksek
A9: UAT-TKT-07 | B9: A. Ticket Listesi (/tickets) | C9: URL paylaşılabilirliği | D9: Analist. | E9: 1. Birkaç filtre uygula. 2. Adres çubuğundaki URL'yi kopyala. 3. Yeni bir sekmede (aynı oturum) yapıştır ve aç. | F9: • Yeni sekme aynı filtreli görünümle açılıyor. | I9: Yüksek
A10: UAT-TKT-08 | B10: B. Ticket Detayı ve Durum Makinesi (/tickets/{id}) | C10: Detay sayfasını açma | D10: Analist · En az 1 ticket var. | E10: 1. Listeden bir ticket satırına tıkla. | F10: • URL /tickets/{id} oluyor. • Üstte "← Ticket listesi" geri bağlantısı. • Ticket başlığı (h1), varsa altında özet (italik). • Aksiyon çubuğu (duruma göre butonlar), Geçmiş (timeline), Yorumlar bölümü ve sağ panel (durum/öncelik/atanan/zaman damgaları) görünüyor. | I10: Yüksek
A11: UAT-TKT-09 | B11: B. Ticket Detayı ve Durum Makinesi (/tickets/{id}) | C11: Açık ticket'ı üstlenme (Açık → İlerlemekte) | D11: Analist · Durumu Açık olan, sana atanmamış bir ticket. | E11: 1. Aksiyon çubuğunda "Üstlen" butonuna tıkla. | F11: • Durum İlerlemekte oluyor, ticket sana atanıyor. • Geçmiş'e (timeline) durum geçişi olayı ekleniyor. • Aksiyon butonları yeni duruma göre değişiyor (Müşteri bekleniyor · Çöz · Bırak görünür). | I11: Yüksek
A12: UAT-TKT-10 | B12: B. Ticket Detayı ve Durum Makinesi (/tickets/{id}) | C12: Çözme ve kapatma (İlerlemekte → Çözüldü → Kapatıldı) | D12: Analist · Sana atanmış, İlerlemekte durumda bir ticket. | E12: 1. "Çöz" butonuna tıkla. 2. Durum Çözüldü olunca "Kapat" butonuna tıkla. | F12: • Adım 1 sonrası durum Çözüldü. • Adım 2 sonrası durum Kapatıldı. • Her geçiş timeline'a işleniyor. | I12: Yüksek
A13: UAT-TKT-11 | B13: B. Ticket Detayı ve Durum Makinesi (/tickets/{id}) | C13: Müşteri bekleme döngüsü | D13: Analist · Sana atanmış, İlerlemekte bir ticket. | E13: 1. "Müşteri bekleniyor" butonuna tıkla. 2. Durum Müşteri Bekleniyor olunca "Devam et"'e tıkla. | F13: • Adım 1 → durum Müşteri Bekleniyor. • Adım 2 → durum tekrar İlerlemekte. | I13: Yüksek
A14: UAT-TKT-12 | B14: B. Ticket Detayı ve Durum Makinesi (/tickets/{id}) | C14: Yanlış üstlenmeyi bırakma (kendi ticket'ın) | D14: Analist · Senin üstlendiğin, İlerlemekte bir ticket. | E14: 1. "Bırak" butonuna tıkla. | F14: • Durum tekrar Açık, atama temizleniyor. • Başka analist artık üstlenebilir. | I14: Yüksek
... A27: UAT-TKT-25 | B27: D. Yorumlar | C27: Yorum arşivleme | D27: Analist · Kendi yazdığın bir yorum. | E27: 1. Kendi yorumunun yanındaki "Arşivle" butonuna tıkla. 2. Açılan onay penceresini onayla. | F27: • Yorum silinmiyor; üzeri çizili + soluk görünüyor, "Arşivlenmiş" rozeti alıyor. Timeline'daki yeri korunuyor. • Başkasının yorumunda "Arşivle" butonu (analist için) görünmüyor; yönetici her yorumu arşivleyebiliyor. | I27: Yüksek

Sheet 05 · Veri Yükleme
A1: İmga UAT — 05 · Veri Yükleme (24 senaryo)
A2: Test ID | B2: Kategori | C2: Senaryo | D2: Ön Koşul | E2: Test Adımları | F2: Beklenen Sonuç | G2: Gerçekleşen Sonuç | H2: Durum | I2: Öncelik | J2: Test Eden | K2: Tarih | L2: Not / Hata No
A3: UAT-ANL-01 | B3: A. Manuel Analiz (/analyze) | C3: Sayfa görünümü | D3: Analist. | E3: 1. Sol menü → Operasyon → Manuel Analiz. | F3: • Başlık "Yorum Analiz Et". • Açıklama: "Müşteri yorumunu yapıştırın. Duygu ve kategori analizi yapılır; kurum otomasyon ayarına göre gerekirse Ticket otomatik açılır." • "Yorum metni" alanı, NPS (opsiyonel, 0–10) alanı ve "Analiz Et" butonu var. | G3: Tüm öğeler birebir mevcut; sayaç '0 / 10.000 karakter'; boş metinde buton pasif. | H3: Geçti | I3: Yüksek | J3: Claude (otomasyon) | K3: 08.07.2026 | L3: —
A4: UAT-ANL-02 | B4: A. Manuel Analiz (/analyze) | C4: Negatif yorum analizi (otomatik Ticket — Yarı/Tam otomatik) | D4: Analist · Kurum otomasyon modu Yarı otomatik veya | E4: 1. Metin alanına negatif bir yorum yaz: "Kargom 5 gündür gelmedi, takip numarası da çalışmıyor. Çok kötü bir hizmet." 2. "Analiz Et"'e bas, 1–5 saniye bekle. | F4: • Buton "Analiz ediliyor…" gösterip sonra sonucu döner. • "Analiz sonucu" kartı: Duygu NEGATIF (kırmızı) + skor, Kategori rozeti + "%.. güven". • Karar kartı (yeşil): "Otomatik Ticket açıldı" + "Kurumunuzun otomasyon ayarı bu yoruma göre yeni bir Ticket açtı." + "Yeni Ticket'a git →". • Linke tıklayınca yeni ticket'ın detay sayfası açılıyor. | G4: NEGATIF −0.50, kargo %80 güven; yeşil 'Otomatik Ticket açıldı' kartı birebir; Ticket ed2d7b74 açıldı, link detay sayfasını doğru açtı. | H4: Geçti | I4: Yüksek | J4: Claude (otomasyon) | K4: 08.07.2026 | L4: —
A5: UAT-ANL-03 | B5: A. Manuel Analiz (/analyze) | C5: Mükerrer metin (24 saat içinde) | D5: Analist · UAT-ANL-02'deki yorumu az önce analiz etmiş ol. | E5: 1. Aynı metni tekrar yapıştır → "Analiz Et". | F5: • Karar kartı (mavi): "Aynı metin son 24 saatte zaten analiz edildi" + "Tekrar Ticket açılmadı; mevcut Ticket'ın altında çalışmaya devam et." | G5: Mavi 'Aynı metin son 24 saatte zaten analiz edildi' kartı birebir; 'Mevcut Ticket'a git' aynı Ticket'a (ed2d7b74) gitti. | H5: Geçti | I5: Yüksek | J5: Claude (otomasyon) | K5: 08.07.2026 | L5: —
A6: UAT-ANL-04 | B6: A. Manuel Analiz (/analyze) | C6: Manuel modda Ticket açılmaz | D6: Yönetici (modu değiştirmek için) · Kurum modu Manuel. | E6: 1. (Yönetici) Ayarlar'dan otomasyon modunu Manuel yap. 2. (Analist veya yönetici) /analyze → negatif bir yorum analiz et. | F6: • Duygu + kategori normal dönüyor. • Karar kartı (mavi): "Otomasyon modu manuel — Ticket açılmadı" + açıklama "kurum ayarlarını Tam veya Yarı otomatik yap". | G6: NEGATIF −1.00, urun_kalitesi %40; 'Otomasyon modu manuel — Ticket açılmadı' kartı birebir. Mod test sonunda Yarı otomatik'e geri alındı. | H6: Geçti | I6: Yüksek | J6: Claude (otomasyon) | K6: 08.07.2026 | L6: —
A7: UAT-ANL-05 | B7: A. Manuel Analiz (/analyze) | C7: Eşik altı (pozitif yorum, Tam otomatik) | D7: Analist · Kurum modu Tam otomatik. | E7: 1. Pozitif bir yorum yaz: "Kargom çok hızlı geldi, harika hizmet." → Analiz Et. | F7: • Duygu POZITIF. • Karar kartı (mavi): "Eşik altı — Ticket açılmadı". | G7: Pozitif cümle NEGATIF −0.40 sınıflandı (İkincil Tetikleyici, eşleşen: 'kargo') → Tam otomatik modda YANLIŞ otomatik Ticket açıldı (2a766438). Toplu yüklemede de aynı desen görüldü. | H7: Kaldı | I7: Yüksek | J7: Claude (otomasyon) | K7: 08.07.2026 | L7: HATA-02
A8: UAT-ANL-06 | B8: A. Manuel Analiz (/analyze) | C8: Belirsiz kategori | D8: Analist. | E8: 1. Konuyla ilgisiz bir metin yaz: "Bugün hava çok güzel, sahile gittim." → Analiz Et. | F8: • Kategori belirsiz. • Karar kartı (mavi): "Kategori belirsiz — manuel sınıflandırma gerekli". | G8: Kategori belirsiz (%0 güven) + 'Kategori belirsiz — manuel sınıflandırma gerekli' kartı doğru. Not: alakasız metne duygu −0.93 NEGATIF verildi (model kalitesi, HATA-02 ile ilişkili). | H8: Geçti | I8: Yüksek | J8: Claude (otomasyon) | K8: 08.07.2026 | L8: —
A9: UAT-ANL-07 | B9: A. Manuel Analiz (/analyze) | C9: "Yine de Ticket Aç" (manuel zorlama) | D9: Analist · UAT-ANL-04/05/06'daki gibi Ticket açılmamış bir sonuç. | E9: 1. Karar kartının altındaki "Yine de Ticket Aç" butonuna bas. | F9: • Sistem güveni geçersiz kılınıp manuel Ticket açılıyor; ilgili ticket'a yönlendiren bağlantı/onay görünüyor. | G9: KISMEN: yapılandırılmış kategoride (urun_kalitesi) manuel Ticket açıldı (fea02eca). Belirsiz sonuçta buton işlevsiz: API 409 "category 'belirsiz' is not configured"; FE yanlış mesaj gösteriyor ('Bu analiz zaten bir Ticket'a bağlı.'). | H9: Kaldı | I9: Yüksek | J9: Claude (otomasyon) | K9: 08.07.2026 | L9: HATA-03 (kısmen)
A10: UAT-ANL-08 | B10: A. Manuel Analiz (/analyze) | C10: Karakter limiti ve NPS doğrulaması | D10: Analist. | E10: 1. Metin alanını boş bırak → "Analiz Et" butonunun durumuna bak. 2. 10.000 karakteri aşan bir metin yapıştır → sayaç ve butonu gözle. 3. NPS alanına 11 yaz → Analiz Et. | F10: • Boş metinde buton pasif. • Sayaç "{n} / 10.000 karakter"; limit aşılınca kırmızı, buton pasif. • NPS 11 → hata: "NPS 0 ile 10 arasında olmalı." | G10: Boş metin → buton pasif; 10.200 karakterde sayaç kırmızı + buton pasif; NPS 11 gönderimi engellendi (mesaj native tarayıcı doğrulaması). | H10: Geçti | I10: Yüksek | J10: Claude (otomasyon) | K10: 08.07.2026 | L10: HATA-07 (kozmetik)
A11: UAT-ANL-09 | B11: A. Manuel Analiz (/analyze) | C11: İzleyici manuel analiz yapamaz | D11: İzleyici. | E11: 1. /analyze'a gitmeyi dene (menüde görünüyorsa tıkla, yoksa URL'yi yaz). | F11: • İzleyici analiz gönderemiyor (sayfa erişimi engelli ya da gönderimde "Bu işlem için yetkin yok."). | G11: Gerçek izleyici hesabıyla: menüde Veri Yükle/Ayarlar/Yönetim yok; /analyze ve /analyze/upload 'Yetkiniz yok'; API POST /analyze → 403 insufficient permissions; hızlı işlemlerde yükleme kısayolu yok. | H11: Geçti | I11: Kritik | J11: Claude + hulusi | K11: 08.07.2026 | L11: Yan bulgular: HATA-05, HATA-10
A12: UAT-UPL-01 | B12: B. Toplu Yükleme Sihirbazı (/analyze/upload) | C12: Şablon indirme | D12: Analist. | E12: 1. Operasyon → Toplu Yükleme'yi aç. 2. Üstteki "Şablonu İndir" butonuna bas. | F12: • Başlık "Toplu Yükleme"; açıklama: "CSV ya da XLSX yükleyin; metinler arka planda analiz edilir, sonuç Analiz Arşivi'nde görünür." • Şablon imga-toplu-yukleme-sablonu.xlsx adıyla iniyor; içinde yorum kolonu var. | G12: Başlık/açıklama birebir; GET /analyze/batch/template 200; şablon içeriği doğru (yorum/tarih/kaynak/nps + TALIMAT sayfası). | H12: Geçti | I12: Yüksek | J12: Claude (otomasyon) | K12: 08.07.2026 | L12: HATA-08 (dosya adı)
A13: UAT-UPL-02 | B13: B. Toplu Yükleme Sihirbazı (/analyze/upload) | C13: Adım 1: dosya tipi/boyut doğrulaması | D13: Analist. | E13: 1. Sürükle-bırak alanına .txt veya .pdf gibi desteklenmeyen bir dosya bırak. 2. 50 MB'tan büyük bir dosya dene (varsa). | F13: • Yanlış uzantı → "Sadece .csv veya .xlsx dosyaları kabul edilir." • Çok büyük dosya → "Dosya 50 MB sınırını aşıyor." • Alanın altında kural: "CSV, XLSX — en fazla 50 MB, en fazla 10.000 satır". | G13: .txt → 'Sadece .csv veya .xlsx dosyaları kabul edilir.'; 51 MB → 'Dosya 50 MB sınırını aşıyor.'; kural metni mevcut. Üçü de birebir. | H13: Geçti | I13: Yüksek | J13: Claude (otomasyon) | K13: 08.07.2026 | L13: —
... A26: UAT-UPL-15 | B26: C. Geçmiş Yüklemeler (/analyze/upload/history) | C26: Geçmiş listesi | D26: Analist · En az 1 tamamlanmış yükleme. | E26: 1. Toplu Yükleme sayfasından "Geçmiş Yüklemeler"'e git. | F26: • Başlık "Geçmiş Yüklemeler". • Tablo: Tarih, Dosya, Satır, Durum, Başarılı, Hata, Ticket sütunları. • Durum rozetleri renkli (tamamlandı=yeşil, işleniyor=sarı, başarısız=kırmızı). • Her satırda "Analizleri gör →" linki çalışıyor. • Boşken: "Henüz toplu yükleme yok. İlk dosyanızı buradan yükleyebilirsiniz." | G26: Başlık, kolonlar ve filtreli 'Analizleri gör' linki doğru; İptal + Tamamlandı koşuları listede. Kozmetik: 'Tamamlandı' rozeti yeşil değil turuncu. | H26: Geçti | I26: Yüksek | J26: Claude (otomasyon) | K26: 08.07.2026 | L26: HATA-09 (kozmetik)

Sheet 06 · Aksiyon & Uyarılar
A1: İmga UAT — 06 · Aksiyon & Uyarılar (11 senaryo)
A2: Test ID | B2: Kategori | C2: Senaryo | D2: Ön Koşul | E2: Test Adımları | F2: Beklenen Sonuç | G2: Gerçekleşen Sonuç | H2: Durum | I2: Öncelik | J2: Test Eden | K2: Tarih | L2: Not / Hata No
A3: UAT-ACT-01 | B3: A. Aksiyonlar (/action-items) | C3: Liste ve "Bugün dikkat" odağı | D3: Herhangi bir rol · En az bir Açık + Yüksek aksiyon var. | E3: 1. Sol menü → Aksiyonlar. | F3: • Başlık "Aksiyonlar", alt başlık "Yönetici özeti ve SWOT raporlarından çıkarılan veya manuel eklenen takip görevleri." • Üstte "Bugün dikkat" + "{n} yüksek öncelikli açık aksiyon"; 3'ten fazlaysa "Tümünü gör" (status=open & priority=high filtreler). | I3: Orta
A4: UAT-ACT-02 | B4: A. Aksiyonlar (/action-items) | C4: Filtreler (durum / öncelik / arşiv) | D4: Herhangi bir rol. | E4: 1. Durum ve Öncelik açılırlarını değiştir. 2. "Arşivi göster" kutusunu işaretle. 3. Sayfayı yenile (F5) ve URL'yi gözle. | F4: • Liste filtreye göre daralıyor; "{n} kayıt" sayacı güncelleniyor. • Filtreler URL'ye yansıyor; yenilemede korunuyor. • Boşken: "Aksiyon yok." | I4: Orta
A5: UAT-ACT-03 | B5: A. Aksiyonlar (/action-items) | C5: Yeni aksiyon oluşturma | D5: Analist/Yönetici. | E5: 1. "Yeni aksiyon" → modal: Başlık + Açıklama + Öncelik. 2. Başlık veya açıklamayı boş bırakıp "Ekle"'yi dene; sonra doldurup ekle. | F5: • Başlık/açıklama zorunlu (boşken gönderilemez). • Eklenince bildirim "Aksiyon eklendi."; liste güncelleniyor. | I5: Orta
A6: UAT-ACT-04 | B6: A. Aksiyonlar (/action-items) | C6: Durum değiştirme | D6: Analist/Yönetici · Bir aksiyon. | E6: 1. Satırdaki durum açılırından durumu Devam Ediyor → Tamamlandı yap. | F6: • Durum anında güncelleniyor; "Tamamlandı"da tamamlanma zamanı işleniyor. • Geçmiş (aşağıda) ilgili olayı gösteriyor. | I6: Orta
A7: UAT-ACT-05 | B7: A. Aksiyonlar (/action-items) | C7: Geçmiş (audit) görüntüleme | D7: Bir aksiyon (birkaç değişiklik yapılmış). | E7: 1. Satırda "Geçmiş"'e bas. | F7: • Zaman damgalı olaylar: Oluşturuldu / Güncellendi / Durum değişti ("{eski} → {yeni}") / Önceliği değişti / Arşivlendi vb. • Boşsa "Olay yok."; yüklenirken "Geçmiş yükleniyor…". | I7: Orta
A8: UAT-ACT-06 | B8: A. Aksiyonlar (/action-items) | C8: Arşivleme ve geri alma | D8: Analist/Yönetici · Bir aktif aksiyon. | E8: 1. "Arşivle" → onay "Aksiyon arşivlensin mi? (Geri alınabilir)" → onayla. 2. "Arşivi göster" ile arşivli satırı bul → "Geri al". | F8: • Arşivleyince "Arşivlendi."; satır arşivli rozetiyle soluk görünüyor. • Geri alınca "Geri alındı."; satır tekrar aktif. | I8: Orta
A9: UAT-ACT-07 | B9: A. Aksiyonlar (/action-items) | C9: İzleyici salt-okunur | D9: İzleyici. | E9: 1. İzleyici ile Aksiyonlar'ı aç. | F9: • Liste görünüyor ama "Yeni aksiyon", durum değiştirme, arşivleme işlemleri yapılamıyor (butonlar yok / işlem reddediliyor). | I9: Orta
A10: UAT-TRD-01 | B10: B. Trend Uyarıları (/trend-alerts) | C10: Liste ve durum filtresi | D10: Herhangi bir rol · En az bir uyarı var. | E10: 1. Sol menü → Uyarılar. 2. Durum açılırını Aktif / Onaylanmış / Atılmış / Tümü arasında değiştir. | F10: • Başlık "Trend Uyarıları", alt başlık "KPI sapması eşiklerini geçen değişimler. Manuel evaluate ile yeni uyarıları yenileyebilirsiniz." • Her uyarı kartında: başlık, önem rozeti (renkli), oluşturma zamanı, tür, açıklama. • Boşsa: "Bu filtrelerle uyarı yok." | I10: Orta
A11: UAT-TRD-02 | B11: B. Trend Uyarıları (/trend-alerts) | C11: Uyarı onaylama / atma | D11: Herhangi bir rol · Aktif bir uyarı. | E11: 1. Bir aktif uyarıda "Onayla"'ya bas. 2. Başka bir aktif uyarıda "At"'a bas. | F11: • "Onayla" → durum "Onaylandı" (onaylayan + zaman damgalı). • "At" → durum "Atıldı". • Aktif olmayan uyarılarda buton yerine durum metni görünüyor. | I11: Orta
A12: UAT-TRD-03 | B12: B. Trend Uyarıları (/trend-alerts) | C12: "Şimdi Değerlendir" (yalnız yönetici) | D12: Yönetici. | E12: 1. "Şimdi Değerlendir" butonuna bas. | F12: • Bildirim "{n} yeni uyarı." (yeni uyarı yoksa 0 olabilir). • Hata olursa: "Değerlendirme başarısız." | I12: Orta
A13: UAT-TRD-04 | B13: B. Trend Uyarıları (/trend-alerts) | C13: İzleyici/analist değerlendiremez | D13: İzleyici veya Analist. | E13: 1. Uyarılar sayfasını aç; "Şimdi Değerlendir" davranışını gözle. | F13: • Liste okunabiliyor, onayla/at yapılabiliyor; ancak manuel değerlendirme (yalnız yöneticiye ait) bu rollerce yapılamıyor. | I13: Orta

Sheet 07 · Ayarlar
A1: İmga UAT — 07 · Ayarlar (16 senaryo)
A2: Test ID | B2: Kategori | C2: Senaryo | D2: Ön Koşul | E2: Test Adımları | F2: Beklenen Sonuç | G2: Gerçekleşen Sonuç | H2: Durum | I2: Öncelik | J2: Test Eden | K2: Tarih | L2: Not / Hata No
A3: UAT-SET-01 | B3: A. Erişim ve Merkez | C3: Yetkisiz erişim engeli | D3: Analist, sonra İzleyici. | E3: 1. Analist ile /settings'i aç (menüde Ayarlar varsa tıkla, yoksa URL yaz). 2. Aynı şeyi İzleyici ile dene. | F3: • İkisi de "Yetkiniz yok" mesajını görüyor; ayarları değiştiremiyor. | I3: Kritik
A4: UAT-SET-02 | B4: A. Erişim ve Merkez | C4: Ayarlar merkezi ve otomasyon modu | D4: Yönetici. | E4: 1. /settings'i aç → başlık "Ayarlar", 9 alt-sayfa kartını gör. 2. Otomasyon modu bölümünden modu Yarı otomatik → Manuel → Tam otomatik değiştirip kaydet. | F4: • 9 navigasyon kartı görünüyor (Şirket Profili, Gemini API Anahtarları, Yapay Zeka Prompt'ları, Şikayet Kategorileri, SLA Kuralları, KPI Hedefleri, İş Boyutları, Kullanıcılar, Zamanlanmış Brifingler). • Otomasyon modu değişikliği kaydediliyor (manuel analiz davranışı buna göre değişir — bkz. modül 05). | I4: Orta
A5: UAT-SET-03 | B5: B. Şirket Profili (/settings/profile) | C5: Profil kaydetme + "Diğer" sektör doğrulaması | D5: Yönetici. | E5: 1. Sektör, Şirket büyüklüğü, İş tanımı (≤ 500 karakter) alanlarını doldur. 2. Sektörü "Diğer" seç → "Sektör (serbest metin)" alanını boş bırakıp kaydet. 3. Serbest metni doldur → "Kaydet". | F5: • Sektör "Diğer" iken serbest metin zorunlu (boşken kaydetme pasif). • Başarılı kayıt: "Profil kaydedildi." • (Bu bilgiler SWOT/OKR üretiminde kullanılır.) | I5: Orta
A6: UAT-SET-04 | B6: C. Gemini API Anahtarları (/settings/integrations) | C6: Anahtar ekleme + doğrulama | D6: Yönetici · Geçerli bir Gemini anahtarı (AIza…). | E6: 1. Etiket ve API anahtarı alanlarını doldur. 2. Önce AIza ile başlamayan bir değer girip "Ekle"'yi dene. 3. Geçerli anahtarı gir → "Ekle". | F6: • Yanlış önek: "Gemini anahtarları "AIza" ile başlar." • Geçerli anahtar: "Anahtar eklendi."; liste güncelleniyor, yalnız "...XXXX" önizlemesi görünüyor; giriş alanı temizleniyor. • İlk anahtar "Birincil", sonrakiler "Yedek N". | I6: Orta
A7: UAT-SET-05 | B7: C. Gemini API Anahtarları (/settings/integrations) | C7: Sıralama, etiket düzenleme, aç/kapat, silme | D7: Yönetici · En az 2 anahtar. | E7: 1. Tutamağı kullanarak anahtarları sürükleyip sırala. 2. Bir etikete tıklayıp inline düzenle, Enter ile kaydet. 3. Bir anahtarın aktif/pasif anahtarını değiştir. 4. Bir anahtarı sil (çöp ikonu) → onayla. | F7: • Sıralama kaydediliyor (hata olursa "Sıralama kaydedilemedi."). • Etiket güncelleniyor; durum değişiyor. • Silme onayı: "API anahtarı silinsin mi?" → "Anahtar silindi." | I7: Kritik
A8: UAT-SET-06 | B8: D. Şikayet Kategorileri / Taksonomiler (/settings/taxonomies) | C8: Arama, filtre, sistem kategorileri | D8: Yönetici. | E8: 1. Arama kutusuna bir etiket/kod yaz. 2. "Devre dışı kategorileri göster" kutusunu işaretle. | F8: • Liste aramaya göre filtreleniyor ("{n} kayıt"); eşleşme yoksa "Eşleşen kategori yok." • Sistem kategorileri "Sistem" rozetli; silinmez yalnız devre dışı bırakılır. | I8: Orta
A9: UAT-SET-07 | B9: D. Şikayet Kategorileri / Taksonomiler (/settings/taxonomies) | C9: Özel kategori ekleme (kod doğrulaması) | D9: Yönetici. | E9: 1. "Kategori ekle" → modal. 2. Kod alanına geçersiz bir değer yaz (örn. büyük harf/boşluk) → dene. 3. Var olan bir kodu tekrar gir → dene. 4. Geçerli kod (vip_sikayet) + Etiket + birkaç anahtar kelime → "Ekle". | F9: • Geçersiz kod: "Kod snake_case olmalı (lowercase + rakam + alt çizgi)." • Tekrar eden kod: "Bu kod zaten kullanılıyor." • Anahtar kelime kuralları (≤ 64 karakter, ≤ 50 adet) uyarı veriyor. • Başarılı: "Kategori eklendi." | I9: Orta
A10: UAT-SET-08 | B10: D. Şikayet Kategorileri / Taksonomiler (/settings/taxonomies) | C10: Kategori düzenleme + devre dışı + geri yükleme | D10: Yönetici · En az bir özel kategori. | E10: 1. Bir kategoriye tıkla → Etiket/anahtar kelime düzenle → "Kaydet". 2. "Devre dışı bırak" → sonra "Devre dışı göster" ile bul → "Geri yükle". | F10: • Güncelleme: "Kategori güncellendi." • Devre dışı: "Kategori devre dışı bırakıldı." → Geri yükle: "Kategori geri yüklendi." | I10: Orta
A11: UAT-SET-09 | B11: E. KPI Hedefleri (/settings/kpi-goals) | C11: Hedef ekleme ve doğrulamalar | D11: Yönetici. | E11: 1. Metric seçmeden "Hedef ekle"'yi dene. 2. Hedef değere sayı olmayan değer gir → dene. 3. Geçerli: Metric + Hedef değer + Dönem + Başlangıç/Bitiş → "Hedef ekle". 4. Aynı metrik + dönem için ikinci kez eklemeyi dene. | F11: • Metric yok: "Metric seçin."; sayı değil: "Hedef sayı olmalı." • Başarılı: "Hedef eklendi."; tekrar: "Aynı metrik + dönem için hedef zaten var." | I11: Orta
A12: UAT-SET-10 | B12: E. KPI Hedefleri (/settings/kpi-goals) | C12: Hedef silme | D12: Yönetici · Bir KPI hedefi. | E12: 1. Bir hedefin çöp ikonuna bas → onayla. | F12: • Onay sorusu → "Hedef silindi." | I12: Kritik
A13: UAT-SET-11 | B13: F. Zamanlanmış Brifingler (/settings/scheduled-briefings) | C13: Plan oluşturma + yönetme | D13: Yönetici. | E13: 1. Periyot (Aylık/Haftalık), Gün, Saat (0–23), opsiyonel e-posta alıcıları ile "Plan ekle". 2. Listede planı Duraklat/Etkinleştir yap. 3. "Şimdi gönder" ile manuel tetikle. 4. "Sil" ile planı kaldır (onayla). | F13: • Ekleme: "Plan eklendi." • Duraklat/Etkinleştir bildirimleri doğru; "Şimdi gönder" sonrası "Brifing üretildi." ya da "Brifing üretilemedi: …". • Silme onayı → "Plan silindi." • Boşken: "Henüz scheduled briefing yok." | I13: Kritik
A14: UAT-SET-12 | B14: G. Kullanıcılar (/settings/users) | C14: Üyeler + davet gönderme (tek seferlik link) | D14: Yönetici. | E14: 1. "Mevcut üyeler" listesini ve rollerini doğrula. 2. "Yeni davet gönder": e-posta + rol seç → "Davet et". 3. Çıkan tek-seferlik linki "Kopyala" ile al. 4. Aynı e-postaya ikinci davet göndermeyi dene. | F14: • Davet sonrası yeşil kutuda link + uyarı "…kapatınca bir daha gösterilmez."; kopyalayınca "Kopyalandı." • E-posta boşsa: "E-posta zorunlu."; tekrar davet: "Bu e-posta için açık davet zaten var." | I14: Orta
... A18: UAT-SET-16 | B18: I. İş Boyutları (/settings/business-dimensions) | C18: Boyut yapılandırma | D18: Yönetici. | E18: 1. Bir boyut kartında (Müşteri Segmenti / Ürün Grubu / Kanal / Müşteri Kademesi) Görünen ad, CSV kolon eşleşmesi, İzin verilen değerler doldur, "Aktif" işaretle → "Kaydet". 2. Sonra "Sil" ile yapılandırmayı kaldır (onayla). | F18: • Kaydetme: "Boyut kaydedildi."; silme onayı → "Silindi." | I18: Kritik

Sheet 08 · Yönetim - Admin
A1: İmga UAT — 08 · Yönetim / Admin (12 senaryo)
A2: Test ID | B2: Kategori | C2: Senaryo | D2: Ön Koşul | E2: Test Adımları | F2: Beklenen Sonuç | G2: Gerçekleşen Sonuç | H2: Durum | I2: Öncelik | J2: Test Eden | K2: Tarih | L2: Not / Hata No
A3: UAT-ADM-01 | B3: A. Erişim kontrolü | C3: "Yönetim" menüsü yalnız süper-yöneticide | D3: Sırasıyla Süper-yönetici, Yönetici, Analist. | E3: 1. Süper-yönetici ile giriş yap → sol menüde "Yönetim" başlığı + altında Kurumlar / LLM Denetimi / Karar Geçmişi / Prompt Şablonları / Bekleyen Bildirimler. 2. Yönetici ve Analist ile giriş yap → menüye bak. 3. Analist ile doğrudan /admin/tenants URL'sini yaz. | F3: • Yönetim bölümü yalnız süper-yöneticide görünüyor. • Yönetici/Analist menüde bu bölümü hiç görmüyor. • Doğrudan URL → "Yetkiniz yok" mesajı. | I3: Kritik
A4: UAT-ADM-02 | B4: B. Kurumlar (/admin/tenants) | C4: Kurum listesi | D4: Süper-yönetici. | E4: 1. Yönetim → Kurumlar'ı aç. | F4: • Başlık "Kurumlar", alt başlık "Süper-yönetici görünümü. Kurum oluştur, düzenle, davet gönder veya soft-delete." • Tablo: İsim, Slug, Plan, Otomasyon, Oluşturuldu + satır aksiyonları (Düzenle / Davet / Sil). • Hiç kurum yoksa: "Henüz kurum yok" + "+ Yeni Kurum". | I4: Yüksek
A5: UAT-ADM-03 | B5: B. Kurumlar (/admin/tenants) | C5: Yeni kurum oluşturma + ilk admin daveti (tek seferlik link) | D5: Süper-yönetici. | E5: 1. "+ Yeni Kurum" → İsim yaz (Slug otomatik üretilir). 2. Slug'a geçersiz karakter (büyük harf/boşluk) gir → uyarıyı gözle. 3. Plan + Otomasyon seç; "İlk admin daveti gönder"'i aç → e-posta + tam ad gir. 4. "Oluştur". 5. Çıkan davet linkini "Kopyala" ile al → "Tamam, paylaştım". | F5: • Slug yalnız küçük harf/rakam/tire kabul ediyor; geçersizde uyarı. • Başarıda yeşil onay: "{kurum} oluşturuldu" + "İlk admin için davet linki hazır. Bu link sadece tek sefer gösterilir…" + link + Kopyala. • Tabloda yeni kurum satırı görünüyor. • Aynı slug tekrar: "Bu slug zaten kullanılıyor." | I5: Yüksek
A6: UAT-ADM-04 | B6: B. Kurumlar (/admin/tenants) | C6: Kurum düzenleme (slug değişmez) | D6: Süper-yönetici · Bir kurum. | E6: 1. Bir satırda "Düzenle" → İsim/Plan/Otomasyon değiştir. 2. Slug alanını değiştirmeyi dene. 3. "Kaydet". | F6: • Slug "Slug (değişmez)" olarak pasif. • Kayıt: "Kurum güncellendi." | I6: Yüksek
A7: UAT-ADM-05 | B7: B. Kurumlar (/admin/tenants) | C7: Kuruma davet gönderme | D7: Süper-yönetici · Bir kurum. | E7: 1. Bir satırda "Davet" → e-posta + rol seç → "Davet oluştur". 2. Çıkan linki kopyala. | F7: • "Davet hazır" + tek-seferlik link + Kopyala. • Aynı e-postaya açık davet varsa: "Bu e-posta için zaten açık davet var." | I7: Yüksek
A8: UAT-ADM-06 | B8: B. Kurumlar (/admin/tenants) | C8: Kurum silme (soft-delete) | D8: Süper-yönetici · Silinebilecek bir test kurumu. | E8: 1. Bir test kurumunda "Sil" → uyarı penceresini oku → "Sil". | F8: • Uyarı: "…Tüm verisi soft-delete edilir; gerekirse veritabanı seviyesinde geri yüklenebilir. Aktif kullanıcılar artık bu kurumu göremez." • Onayda: "Kurum silindi" + "{kurum} arşivlendi (soft-delete)." • Kurum listeden kalkıyor; kullanıcılar kurum seçicide artık göremiyor. | I8: Kritik
A9: UAT-ADM-07 | B9: C. LLM Denetimi (/admin/llm-audit) | C9: LLM çağrı denetim listesi | D9: Süper-yönetici · Daha önce LLM çağrısı yapılmış (SWOT/brifing vb.). | E9: 1. Yönetim → LLM Denetimi'ni aç. 2. Tür ve sonuç (başarılı/hata) filtrelerini değiştir. 3. Bir satırı genişlet (detay). | F9: • Başlık "LLM Çağrı Denetimi". • 3 özet kart: son 30 gün toplam çağrı, hata sayısı, toplam token. • Filtreler URL'ye yansıyor; "{n} kayıt" sayacı doğru. • Satır detayında prompt hash, sağlayıcı, token (giriş/çıkış), hata mesajı (varsa). • Boşsa "Kayıt yok." | I9: Yüksek
A10: UAT-ADM-08 | B10: D. Karar Geçmişi (/admin/decision-audit) | C10: Karar geçmişi listesi ve filtre | D10: Süper-yönetici · Bazı kararlar alınmış (onay/red/atama/hedef). | E10: 1. Yönetim → Karar Geçmişi'ni aç. 2. Karar tipi filtresini değiştir. 3. Bir satırı genişlet. | F10: • Başlık "Karar Geçmişi". • Karar tipleri Türkçe etiketli (örn. "Yönetici özeti onaylandı", "KPI hedefi konuldu"). • Detayda gerekçe + payload (varsa). Boşsa "Kayıt yok." | I10: Yüksek
A11: UAT-ADM-09 | B11: E. Prompt Şablonları (/admin/prompt-templates) | C11: Şablon görüntüleme + kuruma özel oluşturma | D11: Süper-yönetici. | E11: 1. Yönetim → Prompt Şablonları'nı aç. 2. Soldan bir şablon seç (örn. "SWOT Analizi"). 3. Sistem istemi / Kullanıcı istem şablonu alanını düzenle. 4. "Kuruma özel oluştur" (varsayılansa) veya "Özelleştirmeyi güncelle". | F11: • Başlık "Prompt Şablonları". • Şablonlar "varsayılan" / "özel" rozetli. • Kaydetme: "Kuruma özel şablon oluşturuldu." / "Özelleştirme güncellendi." | I11: Yüksek
A12: UAT-ADM-10 | B12: E. Prompt Şablonları (/admin/prompt-templates) | C12: Test çalıştırması ve özelleştirme silme | D12: Süper-yönetici · Kuruma özel bir şablon. | E12: 1. "Test çalıştırması" bölümünde Variables (JSON) gir → geçersiz JSON ile "Test et"'i dene; sonra geçerli JSON ile dene. 2. "Özelleştirmeyi sil" → onay popup'ını onayla. | F12: • Geçersiz JSON: "Variables JSON parse edilemedi." • Geçerli: "Test başarılı (…)." + render çıktısı görünür. • Silme onayı "Özelleştirme silinsin? Kurum varsayılana döner." → "Özelleştirme silindi." | I12: Kritik
A13: UAT-ADM-11 | B13: F. Bekleyen Bildirimler (/pending-webhooks) | C13: Bekleyen bildirim kuyruğu | D13: Süper-yönetici · SLA modu Manuel ve en az bir SLA ihlali oluşmuş. | E13: 1. Yönetim → Bekleyen Bildirimler'i aç. 2. Sekmeler arasında geç: Bekleyen / Gönderildi / Başarısız / İptal / Hepsi. | F13: • Başlık "Bekleyen Bildirimler", alt başlık "Manuel modda tetiklenen SLA bildirimleri. Buradan onay vererek Slack/Teams kanallarına gönder veya iptal et." • Her satır: kural adı, hedef (Slack/Teams), durum rozeti, tarih. • Boşken (Bekleyen): "Bekleyen webhook yok. SLA breach olduğunda burada görünecek." | I13: Yüksek
A14: UAT-ADM-12 | B14: F. Bekleyen Bildirimler (/pending-webhooks) | C14: Bildirim gönderme / iptal | D14: Süper-yönetici · Bekleyen bir bildirim. | E14: 1. Bekleyen bir satırda "Gönder"'e bas. 2. Başka bir bekleyende "İptal"'e bas. | F14: • Gönder → "Bildirim gönderildi." (durum "Gönderildi"); hata olursa "Gönderim başarısız." • İptal → "İptal edildi." | I14: Yüksek

Sheet 09 · Roller & Yetkiler (RBAC)
A1: İmga UAT — 09 · Roller & Yetkiler (RBAC) (6 senaryo)
A2: Test ID | B2: Kategori | C2: Senaryo | D2: Ön Koşul | E2: Test Adımları | F2: Beklenen Sonuç | G2: Gerçekleşen Sonuç | H2: Durum | I2: Öncelik | J2: Test Eden | K2: Tarih | L2: Not / Hata No
A3: UAT-RBAC-01 | B3: A. Sayfa erişimi | C3: Menü ve sayfa görünürlüğü | E3: doğrudan URL ile erişimi dene. | Sayfa | Süper-yön. | Yönetici | Analist | İzleyici | |---|---|---|---|---| | Panel (/) | ✓ | ✓ | ✓ | ✓ | | Yönetici Özeti (/executive-briefing) | ✓ | ✓ | ✓ | ✓ | | Aksiyonlar (/action-items) | ✓ | ✓ | ✓ | ✓ (okur) | | Uyarılar (/trend-alerts) | ✓ | ✓ | ✓ | ✓ | | Strateji (/strategy) | ✓ | ✓ | ✓ | ✓ | | İçgörüler (/insights) | ✓ | ✓ | ✓ | ✓ | | Analiz Arşivi (/reviews) | ✓ | ✓ | ✓ | ✓ | | Raporlar (/reports) | ✓ | ✓ | ✓ | ✓ | | Ticket'lar (/tickets) | ✓ | ✓ | ✓ | ✓ (okur) | | Manuel Analiz (/analyze) | ✓ | ✓ | ✓ | ✗ | | Toplu Yükleme (/analyze/upload) | ✓ | ✓ | ✓ | ✗ | | Ayarlar (/settings + alt) | ✓ | ✓ | ✗ | ✗ | | Yönetim (/admin/) | ✓ | ✗ | ✗ | ✗ | | F3: • Tablodaki ✗ olan yerlerde sayfa "Yetkiniz yok" veriyor ya da menüde hiç görünmüyor. • "Yönetim" bölümü yalnız süper-yöneticide. | I3: Kritik
A4: UAT-RBAC-02 | B4: B. Ticket yetkileri | C4: Ticket durum geçişleri rol bazlı | E4: varlığını doğrula. | İşlem | Yönetici | Analist | İzleyici | |---|---|---|---| | Üstlen (Açık→İlerlemekte) | ✓ | ✓ | ✗ | | Çöz / Müşteri bekle / Devam et | ✓ | ✓ | ✗ | | Kapat (Çözüldü→Kapatıldı) | ✓ | ✓ | ✗ | | Bırak (kendi ticket'ı) | ✓ | ✓ | ✗ | | İptal (Açık→İptal) | ✓ | ✓ | ✗ | | İptal (İlerlemekte→İptal) | ✓ | ✗ | ✗ | | Yeniden aç (Kapatıldı→) | ✓ | ✗ | ✗ | | İptali geri al (İptal→) | ✓ | ✗ | ✗ | | F4: • İzleyiciye hiçbir durum butonu görünmüyor. • Analist İlerlemekte'den iptal edemiyor; kapatılmış/iptal ticket'ı yeniden açamıyor (bunlar yöneticiye özel). | I4: Kritik
A5: UAT-RBAC-03 | B5: B. Ticket yetkileri | C5: Yorum ve atama yetkileri | E5: | İşlem | Yönetici | Analist | İzleyici | |---|---|---|---| | İç not yaz | ✓ | ✓ | ✓ | | Müşteri yanıtı yaz (aktif ticket) | ✓ | ✓ | ✗ | | Müşteri yanıtı (Kapalı/İptal ticket) | ✗ | ✗ | ✗ | | Kendi yorumunu arşivle | ✓ | ✓ | ✓ | | Başkasının yorumunu arşivle | ✓ | ✗ | ✗ | | Herkesi ata | ✓ | ✗ | ✗ | | Yalnız kendini ata | — | ✓ | ✗ | | F5: • İzleyicide "Müşteri yanıtı" seçeneği yok/pasif. • Analist başkasının yorumunu arşivleyemiyor, başkasını atayamıyor. | I5: Kritik
A6: UAT-RBAC-04 | B6: C. Veri yükleme ve analiz yetkileri | C6: Analiz / yükleme rol bazlı | E6: | İşlem | Yönetici | Analist | İzleyici | |---|---|---|---| | Manuel analiz gönder | ✓ | ✓ | ✗ | | Toplu dosya yükle | ✓ | ✓ | ✗ | | Şablon indir | ✓ | ✓ | ✓ | | Geçmiş yüklemeleri gör | ✓ | ✓ | ✓ | | Analizi Ticket'a dönüştür | ✓ | ✓ | ✗ | | Kararı düzelt | ✓ | ✓ | ✗ | | F6: • İzleyici analiz gönderemiyor/yükleyemiyor; denerse "Bu işlem için yetkin yok." ya da sayfa erişimi engelli. | I6: Kritik
A7: UAT-RBAC-05 | B7: D. Ayar ve yönetim yetkileri | C7: Ayar/aksiyon/uyarı/yönetim yetkileri | E7: | İşlem | Süper-yön. | Yönetici | Analist | İzleyici | |---|---|---|---|---| | Otomasyon modu değiştir | ✓ | ✓ | ✗ | ✗ | | Kategori/SLA/KPI/Profil düzenle | ✓ | ✓ | ✗ | ✗ | | Kullanıcı davet et (kendi kurumu) | ✓ | ✓ | ✗ | ✗ | | Aksiyon oluştur / durum değiştir | ✓ | ✓ | ✓ | ✗ | | Uyarı onayla / at | ✓ | ✓ | ✓ | ✓ | | Uyarı "Şimdi Değerlendir" | ✓ | ✓ | ✗ | ✗ | | Kurum oluştur/sil | ✓ | ✗ | ✗ | ✗ | | LLM/Karar denetimi gör | ✓ | ✗ | ✗ | ✗ | | F7: • Tablodaki ✗ yerlerde işlem yapılamıyor (buton yok / "Yetkiniz yok" / reddediliyor). | I7: Kritik
A8: UAT-RBAC-06 | B8: E. Kurumlar arası izolasyon (kritik) | C8: Bir kurumun verisi başka kurumda görünmemeli | D8: Çok-kurumlu kullanıcı (Kurum A + Kurum B). | E8: 1. Kurum A'da bir ticket'ın/analizin ID'sini (URL'den) not al. 2. Kurum B'ye geç. 3. Kurum A'daki o ID'yi B bağlamındayken doğrudan URL ile açmayı dene (örn. /tickets/{A-ticket-id}). | F8: • Kurum B bağlamındayken Kurum A'nın kaydı görünmüyor (bulunamadı / erişim yok). Kurum verileri tamamen izole. | I8: Kritik

Sheet 10 · Genel - Çapraz
A1: İmga UAT — 10 · Genel / Çapraz (11 senaryo)
A2: Test ID | B2: Kategori | C2: Senaryo | D2: Ön Koşul | E2: Test Adımları | F2: Beklenen Sonuç | G2: Gerçekleşen Sonuç | H2: Durum | I2: Öncelik | J2: Test Eden | K2: Tarih | L2: Not / Hata No
A3: UAT-GEN-01 | B3: A. Terminoloji ve dil tutarlılığı | C3: "Bilet" kelimesi hiçbir yerde olmamalı | D3: Herhangi bir rol. | E3: 1. Ticket'la ilgili tüm sayfaları gez (Panel, Ticket'lar, ticket detayı, Manuel Analiz karar kartları, Toplu Yükleme özeti, Analiz Arşivi). 2. Her sayfada tarayıcı içi aramayla (Ctrl+F) "bilet" kelimesini ara. | F3: • Hiçbir ekranda "bilet" geçmiyor; her yerde "Ticket" kullanılıyor. • Türkçe ekleri apostrofla: "Ticket'lar", "Ticket'a". • "bilet" bulursan: Düşük/Orta önemli hata olarak satır satır raporla. | I3: Düşük
A4: UAT-GEN-02 | B4: A. Terminoloji ve dil tutarlılığı | C4: "Kurum" terminolojisi ve iç jargon sızıntısı | D4: Herhangi bir rol. | E4: 1. Kullanıcıya görünen metinlerde "tenant" kelimesini ara (Ctrl+F). 2. Teknik jargon ("Job", "Batch", "Render", "payload", "override", "bridge") kullanıcıya görünen metinlerde geçiyor mu bak. | F4: • Kullanıcı yüzeyinde "tenant" yerine "Kurum" kullanılıyor. • SWOT / OKR / KPI / NPS gibi standart iş terimleri korunur (bunlar hata değil). • Ham teknik jargon kullanıcı metinlerinde görünmemeli. | I4: Düşük
